<?xml version="1.0" encoding="utf-8"?>
<!-- This URDF was automatically created by SolidWorks to URDF Exporter! Originally created by Stephen Brawner (brawner@gmail.com) 
     Commit Version: 1.6.0-4-g7f85cfe  Build Version: 1.6.7995.38578
     For more information, please see http://wiki.ros.org/sw_urdf_exporter -->
<robot
  name="carry_arm">
  <link name="dummy">
    <inertial>
      <origin xyz="0 0 0" rpy="0 0 0" />
      <mass value="1" />
      <inertia ixx="1e-9" ixy="0" ixz="0" iyy="1e-9" iyz="0" izz="1e-9" />
    </inertial>
  </link>
  <link
    name="arm0_link">
    <inertial>
      <origin
        xyz="-0.012377 -0.020974 0.016204"
        rpy="0 0 0" />
      <mass
        value="0.17426" />
      <inertia
        ixx="0.0002445"
        ixy="-7.8656E-22"
        ixz="9.2644E-20"
        iyy="0.0004811"
        iyz="8.1429E-19"
        izz="0.0002445" />
    </inertial>
    <visual>
      <origin
        xyz="0 0 0"
        rpy="0 0 0" />
      <geometry>
        <mesh
          filename="arm0_link.STL" />
      </geometry>
      <material
        name="">
        <color
          rgba="0.79216 0.81961 0.93333 1" />
      </material>
    </visual>
    <collision>
      <origin
        xyz="0 0 0"
        rpy="0 0 0" />
      <geometry>
        <mesh
          filename="arm0_link.STL" />
      </geometry>
    </collision>
  </link>
  <joint name="dymmy_joint" type="fixed"> 
    <origin
      xyz="0.012377 0.016204 0.014238"
      rpy="0 0 0" />
    <parent
      link="dummy" />
    <child
      link="arm0_link" />
  </joint>
  <link
    name="arm1_link">
    <inertial>
      <origin
        xyz="-1.259E-11 0.016476 2.6113E-11"
        rpy="0 0 0" />
      <mass
        value="0.2407" />
      <inertia
        ixx="0.00031084"
        ixy="1.0013E-13"
        ixz="8.9599E-12"
        iyy="0.00040073"
        iyz="-4.7186E-13"
        izz="0.0003106" />
    </inertial>
    <visual>
      <origin
        xyz="0 0 0"
        rpy="1.5708 0 0" />
      <geometry>
        <mesh
          filename="arm1_link.STL" />
      </geometry>
      <material
        name="">
        <color
          rgba="0.79216 0.81961 0.93333 1" />
      </material>
    </visual>
    <collision>
      <origin
        xyz="0 0 0"
        rpy="1.5708 0 0" />
      <geometry>
        <mesh
          filename="arm1_link.STL" />
      </geometry>
    </collision>
  </link>
  <joint
    name="arm1_joint"
    type="continuous">
    <origin
      xyz="-0.012377 -0.016204 -0.014238"
      rpy="0 0 0" />
    <parent
      link="arm0_link" />
    <child
      link="arm1_link" />
    <axis
      xyz="0 0 1" />
  </joint>
  <link
    name="arm2_link">
    <inertial>
      <origin
        xyz="3.7309E-05 0.059852 3.1191E-09"
        rpy="0 0 0" />
      <mass
        value="0.069332" />
      <inertia
        ixx="2.9097E-05"
        ixy="-9.6545E-08"
        ixz="-1.8985E-12"
        iyy="6.3303E-06"
        iyz="-5.3135E-12"
        izz="2.9192E-05" />
    </inertial>
    <visual>
      <origin
        xyz="0 0 0"
        rpy="1.5708 0 0" />
      <geometry>
        <mesh
          filename="arm2_link.STL" />
      </geometry>
      <material
        name="">
        <color
          rgba="0.75294 0.75294 1 1" />
      </material>
    </visual>
    <collision>
      <origin
        xyz="0 0 0"
        rpy="1.5708 0 0" />
      <geometry>
        <mesh
          filename="arm2_link.STL" />
      </geometry>
    </collision>
  </link>
  <joint
    name="arm2_joint"
    type="continuous">
    <origin
      xyz="0 0 0.1"
      rpy="0 0 0" />
    <parent
      link="arm1_link" />
    <child
      link="arm2_link" />
    <axis
      xyz="0 1 0" />
  </joint>
  <link
    name="arm3_link">
    <inertial>
      <origin
        xyz="-0.000482917389346194 -0.0696640474343872 2.71894506215231E-09"
        rpy="0 0 0" />
      <mass
        value="0.0698090885612059" />
      <inertia
        ixx="2.99472481620794E-05"
        ixy="-1.06390115585764E-07"
        ixz="-4.01944454880557E-13"
        iyy="6.20988850427198E-06"
        iyz="-4.49828166769348E-12"
        izz="3.01404678861509E-05" />
    </inertial>
    <visual>
      <origin
        xyz="0 0 0"
        rpy="-1.5708 0 0" />
      <geometry>
        <mesh
          filename="arm3_link.STL" />
      </geometry>
      <material
        name="">
        <color
          rgba="0.752941176470588 0.752941176470588 1 1" />
      </material>
    </visual>
    <collision>
      <origin
        xyz="0 0 0"
        rpy="-1.5708 0 0" />
      <geometry>
        <mesh
          filename="arm3_link.STL" />
      </geometry>
    </collision>
  </link>
  <joint
    name="arm3_joint"
    type="continuous">
    <origin
      xyz="0 0 0.13"
      rpy="0 0 0" />
    <parent
      link="arm2_link" />
    <child
      link="arm3_link" />
    <axis
      xyz="0 1 0" />
  </joint>
  <link
    name="arm4_link">
    <inertial>
      <origin
        xyz="-4.1672E-10 -0.083524 3.166E-10"
        rpy="0 0 0" />
      <mass
        value="0.2407" />
      <inertia
        ixx="0.00031084"
        ixy="4.8915E-12"
        ixz="9.0043E-12"
        iyy="0.00040073"
        iyz="-4.7032E-12"
        izz="0.0003106" />
    </inertial>
    <visual>
      <origin
        xyz="0 0 0"
        rpy="-1.5708 0 0" />
      <geometry>
        <mesh
          filename="arm4_link.STL" />
      </geometry>
      <material
        name="">
        <color
          rgba="0.79216 0.81961 0.93333 1" />
      </material>
    </visual>
    <collision>
      <origin
        xyz="0 0 0"
        rpy="-1.5708 0 0" />
      <geometry>
        <mesh
          filename="arm4_link.STL" />
      </geometry>
    </collision>
  </link>
  <joint
    name="arm4_joint"
    type="continuous">
    <origin
      xyz="0 0 0.13"
      rpy="0 0 0" />
    <parent
      link="arm3_link" />
    <child
      link="arm4_link" />
    <axis
      xyz="0 1 0" />
  </joint>
  <link
    name="arm5_link">
    <inertial>
      <origin
        xyz="2.7756E-17 -1.3878E-17 0.0067365"
        rpy="0 0 0" />
      <mass
        value="0.17426" />
      <inertia
        ixx="0.0002445"
        ixy="2.0581E-20"
        ixz="7.6233E-21"
        iyy="0.0002445"
        iyz="6.2281E-21"
        izz="0.0004811" />
    </inertial>
    <visual>
      <origin
        xyz="0 0 0"
        rpy="0 0 0" />
      <geometry>
        <mesh
          filename="arm5_link.STL" />
      </geometry>
      <material
        name="">
        <color
          rgba="0.79216 0.81961 0.93333 1" />
      </material>
    </visual>
    <collision>
      <origin
        xyz="0 0 0"
        rpy="0 0 0" />
      <geometry>
        <mesh
          filename="arm5_link.STL" />
      </geometry>
    </collision>
  </link>
  <joint
    name="arm5_joint"
    type="continuous">
    <origin
      xyz="0 0 0.1"
      rpy="0 0 0" />
    <parent
      link="arm4_link" />
    <child
      link="arm5_link" />
    <axis
      xyz="0 0 1" />
  </joint>
  <link
    name="arm6_link">
    <inertial>
      <origin
        xyz="0.06 0.06 0.0067365"
        rpy="0 0 0" />
      <mass
        value="0.17426" />
      <inertia
        ixx="0.0002445"
        ixy="-9.4869E-20"
        ixz="-1.2725E-20"
        iyy="0.0002445"
        iyz="1.2875E-19"
        izz="0.0004811" />
    </inertial>
    <visual>
      <origin
        xyz="0 0 0"
        rpy="0 0 0" />
      <geometry>
        <mesh
          filename="arm6_link.STL" />
      </geometry>
      <material
        name="">
        <color
          rgba="0.79216 0.81961 0.93333 1" />
      </material>
    </visual>
    <collision>
      <origin
        xyz="0 0 0"
        rpy="0 0 0" />
      <geometry>
        <mesh
          filename="arm6_link.STL" />
      </geometry>
    </collision>
  </link>
  <joint
    name="arm6_joint"
    type="continuous">
    <origin
      xyz="-0.06 0.06 0"
      rpy="0 1.5708 3.14159" />
    <parent
      link="arm5_link" />
    <child
      link="arm6_link" />
    <axis
      xyz="0 -1 0" />
  </joint>
</robot>